Workbook
Name Slicer_case_type: #N/A
Name Slicer_cases.case_doctors.doctor_role: #N/A
Name Slicer_department_name: #N/A
Name Slicer_diagnoses: #N/A
Name Slicer_doctor_id: #N/A
Name Slicer_gender: #N/A
Name Slicer_patient_id: #N/A
Name Slicer_payment_method: #N/A

Sheet users
A1: user_id | B1: username | C1: password | D1: role | E1: staff_id
A2: 1 | B2: admin_amit | C2: $2y$10$adminpass01 | D2: Admin | E2: 1
A3: 2 | B3: admin_suresh | C3: $2y$10$adminpass02 | D3: Admin | E3: 11
A4: 3 | B4: admin_vinod | C4: $2y$10$adminpass03 | D4: Admin | E4: 21
A5: 4 | B5: admin_mukesh | C5: $2y$10$adminpass04 | D5: Admin | E5: 36
A6: 5 | B6: recept_neha | C6: $2y$10$receppass01 | D6: Receptionist | E6: 2
A7: 6 | B7: recept_vikas | C7: $2y$10$receppass02 | D7: Receptionist | E7: 7
A8: 7 | B8: recept_priya | C8: $2y$10$receppass03 | D8: Receptionist | E8: 12
A9: 8 | B9: recept_ramesh | C9: $2y$10$receppass04 | D9: Receptionist | E9: 17
A10: 9 | B10: recept_sneha | C10: $2y$10$receppass05 | D10: Receptionist | E10: 22
A11: 10 | B11: recept_harish | C11: $2y$10$receppass06 | D11: Receptionist | E11: 28
A12: 11 | B12: recept_komal | C12: $2y$10$receppass07 | D12: Receptionist | E12: 33
A13: 12 | B13: recept_ajay | C13: $2y$10$receppass08 | D13: Receptionist | E13: 38
... A33: 32 | B33: pharma_tasneem | C33: $2y$10$pharmapass09 | D33: Pharmacist | E33: 45

Sheet test_results
A1: result_id | B1: record_id | C1: test_id | D1: result | E1: test_date
A2: 1 | B2: 1 | C2: 1 | D2: Normal ECG, no abnormalities detected | E2: 45667
A3: 2 | B3: 2 | C3: 2 | D3: Cholesterol slightly elevated, LDL 140 mg/dL | E3: 45668
A4: 3 | B4: 3 | C4: 3 | D4: Chest X-Ray normal, no fractures | E4: 45669
A5: 4 | B5: 4 | C5: 4 | D5: Fasting blood sugar 95 mg/dL | E5: 45670
A6: 5 | B6: 5 | C6: 5 | D6: Ultrasound: normal abdominal organs | E6: 45671
A7: 6 | B7: 6 | C7: 6 | D7: CBC normal, WBC 6,500/mm3 | E7: 45672
A8: 7 | B8: 7 | C8: 7 | D8: TSH normal at 2.1 μIU/mL | E8: 45673
A9: 8 | B9: 8 | C9: 8 | D9: Urine routine: no infection detected | E9: 45674
A10: 9 | B10: 9 | C10: 9 | D10: MRI Brain: no abnormal findings | E10: 45675
A11: 10 | B11: 10 | C11: 10 | D11: HbA1c 6.2%, pre-diabetic range | E11: 45676
A12: 11 | B12: 11 | C12: 11 | D12: Liver function normal, ALT 25 U/L | E12: 45689
A13: 12 | B13: 12 | C13: 12 | D13: Kidney function normal, Creatinine 0.9 mg/dL | E13: 45690
... A41: 40 | B41: 40 | C41: 40 | D41: Biopsy: benign tissue | E41: 45757

Sheet staff
A1: staff_id | B1: name | C1: role | D1: phone | E1: email
A2: 1 | B2: Amit Sharma | C2: Admin | D2: 9000000001 | E2: amit.sharma@lifecare.com
A3: 2 | B3: Neha Verma | C3: Receptionist | D3: 9000000002 | E3: neha.verma@lifecare.com
A4: 3 | B4: Rohit Mehta | C4: Accountant | D4: 9000000003 | E4: rohit.mehta@lifecare.com
A5: 4 | B5: Pooja Singh | C5: Nurse | D5: 9000000004 | E5: pooja.singh@lifecare.com
A6: 5 | B6: Ankit Patel | C6: Pharmacist | D6: 9000000005 | E6: ankit.patel@lifecare.com
A7: 6 | B7: Sunita Rao | C7: Nurse | D7: 9000000006 | E7: sunita.rao@lifecare.com
A8: 7 | B8: Vikas Khanna | C8: Receptionist | D8: 9000000007 | E8: vikas.khanna@lifecare.com
A9: 8 | B9: Kiran Joshi | C9: Lab Technician | D9: 9000000008 | E9: kiran.joshi@lifecare.com
A10: 9 | B10: Rahul Nair | C10: Pharmacist | D10: 9000000009 | E10: rahul.nair@lifecare.com
A11: 10 | B11: Meena Iyer | C11: Nurse | D11: 9000000010 | E11: meena.iyer@lifecare.com
A12: 11 | B12: Suresh Kumar | C12: Admin | D12: 9000000011 | E12: suresh.kumar@lifecare.com
A13: 12 | B13: Priya Malhotra | C13: Receptionist | D13: 9000000012 | E13: priya.malhotra@lifecare.com
... A46: 45 | B46: Tasneem Siddiqui | C46: Pharmacist | D46: 9000000045 | E46: tasneem.siddiqui@lifecare.com

Sheet records
A1: record_id | B1: patient_id | C1: doctor_id | D1: visited_date | E1: note
A2: 1 | B2: 1 | C2: 5 | D2: 45667.438 | E2: Patient complained of chest pain. ECG advised.
A3: 2 | B3: 2 | C3: 12 | D3: 45668.5 | E3: Follow-up visit. Blood pressure stable.
A4: 3 | B4: 3 | C4: 18 | D4: 45669.406 | E4: Minor injuries due to accident. X-ray suggested.
A5: 4 | B5: 4 | C5: 9 | D5: 45670.604 | E5: Routine antenatal check-up.
A6: 5 | B6: 5 | C6: 20 | D6: 45671.708 | E6: Patient brought in by police. Observation required.
A7: 6 | B7: 6 | C7: 3 | D7: 45672.469 | E7: Fever and cough for 3 days. Medication prescribed.
A8: 7 | B8: 7 | C8: 7 | D8: 45673.521 | E8: General health check-up.
A9: 8 | B9: 8 | C9: 14 | D9: 45674.417 | E9: Skin rash observed. Allergy suspected.
A10: 9 | B10: 9 | C10: 22 | D10: 45675.646 | E10: Severe headache. MRI advised.
A11: 10 | B11: 10 | C11: 30 | D11: 45676.479 | E11: Follow-up for diabetes management.
A12: 11 | B12: 11 | C12: 8 | D12: 45689.458 | E12: Child showing symptoms of viral fever.
A13: 12 | B13: 12 | C13: 16 | D13: 45690.573 | E13: Joint pain reported. Physiotherapy suggested.
... A51: 50 | B51: 50 | C51: 50 | D51: 45787.479 | E51: Routine health screening.

Sheet prescription_items
A1: prescription_item_id | B1: prescription_id | C1: medicine_id | D1: lab_test | E1: dosage | F1: duration
A2: 1 | B2: 1 | C2: 1 | E2: 500mg twice daily | F2: 5 days
A3: 2 | B3: 1 | C3: 11 | D3: ECG | E3: 40mg once daily | F3: 7 days
A4: 3 | B4: 2 | C4: 7 | E4: 5mg once daily | F4: 30 days
A5: 4 | B5: 2 | C5: 9 | D5: Lipid Profile | E5: 10mg once daily | F5: 30 days
A6: 5 | B6: 3 | C6: 31 | D6: X-Ray Chest | E6: 50mg twice daily | F6: 5 days
A7: 6 | B7: 3 | C7: 29 | E7: 4mg once daily | F7: 3 days
A8: 7 | B8: 4 | C8: 25 | D8: Ultrasound | E8: 60000IU once weekly | F8: 8 weeks
A9: 8 | B9: 5 | C9: 20 | D9: Blood Test | E9: 10mg once daily | F9: 7 days
A10: 9 | B10: 6 | C10: 1 | E10: 500mg thrice daily | F10: 5 days
A11: 10 | B11: 6 | C11: 16 | E11: 10ml twice daily | F11: 5 days
A12: 11 | B12: 7 | C12: 28 | E12: 1 tablet daily | F12: 10 days
A13: 12 | B13: 8 | C13: 14 | E13: 10mg once daily | F13: 7 days
A14: 13 | B14: 8 | C14: 33 | E14: 50mg twice daily | F14: 5 days
A15: 14 | B15: 9 | C15: 39 | D15: MRI Brain | E15: 1g injection daily | F15: 3 days
A16: 15 | B16: 10 | C16: 6 | E16: 500mg twice daily | F16: 30 days
A17: 16 | B17: 10 | C17: 22 | E17: 2mg once daily | F17: 30 days
A18: 17 | B18: 11 | C18: 1 | E18: 500mg twice daily | F18: 5 days
A19: 18 | B19: 12 | C19: 12 | E19: 20mg once daily | F19: 14 days
A20: 19 | B20: 12 | C20: 29 | D20: Blood Test | E20: 4mg once daily | F20: 5 days
A21: 20 | B21: 13 | C21: 38 | E21: 1g injection daily | F21: 5 days
A22: 21 | B22: 14 | C22: 9 | D22: BP Monitoring | E22: 10mg once daily | F22: 30 days
A23: 22 | B23: 15 | C23: 40 | D23: Biopsy | E23: 500mg injection daily | F23: 7 days
A24: 23 | B24: 16 | C24: 11 | E24: 40mg once daily | F24: 10 days
A25: 24 | B25: 17 | C25: 32 | E25: 50mg twice daily | F25: 5 days
A26: 25 | B26: 17 | C26: 31 | E26: 50mg twice daily | F26: 5 days
A27: 26 | B27: 18 | C27: 29 | E27: 4mg once daily | F27: 3 days
A28: 27 | B28: 19 | C28: 21 | D28: Blood Sugar Test | E28: 10 units before meals | F28: 30 days
A29: 28 | B29: 20 | C29: 17 | E29: 4mg twice daily | F29: 7 days
A30: 29 | B30: 21 | C30: 43 | E30: 50mg once daily | F30: 30 days
A31: 30 | B31: 22 | C31: 1 | E31: 500mg twice daily | F31: 3 days
A32: 31 | B32: 23 | C32: 31 | D32: MRI Spine | E32: 50mg twice daily | F32: 5 days
A33: 32 | B33: 24 | C33: 25 | E33: 60000IU weekly | F33: 6 weeks
A34: 33 | B34: 25 | C34: 28 | D34: Lab Test | E34: 1 tablet daily | F34: 7 days
A35: 34 | B35: 26 | C35: 7 | E35: 5mg once daily | F35: 30 days
A36: 35 | B36: 27 | C36: 38 | E36: 1g injection daily | F36: 5 days
A37: 36 | B37: 28 | C37: 14 | E37: 10mg once daily | F37: 7 days
A38: 37 | B38: 29 | C38: 39 | D38: Eye Test | E38: 1g injection daily | F38: 3 days
A39: 38 | B39: 30 | C39: 6 | E39: 500mg twice daily | F39: 30 days
A40: 39 | B40: 31 | C40: 1 | E40: 500mg twice daily | F40: 5 days
...

Sheet prescription
A1: prescription_id | B1: record_id | C1: prescription_date
A2: 1 | B2: 1 | C2: 45667.458
A3: 2 | B3: 2 | C3: 45668.521
A4: 3 | B4: 3 | C4: 45669.427
A5: 4 | B5: 4 | C5: 45670.625
A6: 5 | B6: 5 | C6: 45671.729
A7: 6 | B7: 6 | C7: 45672.49
A8: 7 | B8: 7 | C8: 45673.542
A9: 8 | B9: 8 | C9: 45674.438
A10: 9 | B10: 9 | C10: 45675.667
A11: 10 | B11: 10 | C11: 45676.5
A12: 11 | B12: 11 | C12: 45689.479
A13: 12 | B13: 12 | C13: 45690.594
... A51: 50 | B51: 50 | C51: 45787.5

Sheet payments
A1: payment_id | B1: bill_id | C1: payment_date | D1: payment_method | E1: amount
A2: 1 | B2: 1 | C2: 45678 | D2: Cash | E2: 3500
A3: 2 | B3: 2 | C3: 45680 | D3: Card | E3: 4200
A4: 3 | B4: 3 | C4: 45680 | D4: UPI | E4: 1800
A5: 4 | B5: 4 | C5: 45682 | D5: Insurance | E5: 2500
A6: 5 | B6: 5 | C6: 45683 | D6: Cash | E6: 6000
A7: 6 | B7: 6 | C7: 45685 | D7: Card | E7: 3200
A8: 7 | B8: 7 | C8: 45686 | D8: UPI | E8: 1500
A9: 8 | B9: 8 | C9: 45687 | D9: Cash | E9: 2200
A10: 9 | B10: 9 | C10: 45689 | D10: Insurance | E10: 4800
A11: 10 | B11: 10 | C11: 45690 | D11: Card | E11: 3000
A12: 11 | B12: 11 | C12: 45695 | D12: UPI | E12: 2700
A13: 12 | B13: 12 | C13: 45697 | D13: Cash | E13: 3500
... A51: 50 | B51: 50 | C51: 45788 | D51: Cash | E51: 5200

Sheet life_care_hospital
A1: patient_id | B1: patient_name | C1: gender | D1: date_of_birth | E1: phone | F1: email | G1: address | H1: created_at | I1: case_id | J1: case_type | K1: case_date | L1: case_doctor_id | M1: cases.case_doctors.doctor_role | N1: assigned_date | O1: doctor_id | P1: Doctor_name | Q1: doctors_specialization | R1: doctors_phone | S1: doctors_email | T1: doctors_department_id | U1: doctors_created_at | V1: department_name | W1: doctor_description | X1: doctor_availability_id | Y1: doctor_availability_day | Z1: doctor_availability_start_time | AA1: doctor_availability_end_time | AB1: .doctor_availability_is_on_call | AC1: appointment_id | AD1: appointment_date | AE1: appointments.status | AF1: record_id | AG1: patient_visited_date | AH1: doctor_note | AI1: diagnoses_id | AJ1: diagnoses | AK1: prescription_id | AL1: prescription_date | AM1: prescription_item_id | AN1: lab_tests.test_id | AO1: test_name | AP1: lab_tests.cost | AQ1: test_result_id | AR1: test_result | AS1: test_results_date | AT1: .medicine_id | AU1: medicine_name | AV1: medicines_formula | AW1: Doses | AX1: duration | AY1: medicines.price | AZ1: alternative_medicines_id | BA1: alternative_medicines_name | BB1: alternative_medicines_formula | BC1: alternative_medicines_price | BD1: bill_id | BE1: bill_date | BF1: total_amount | BG1: invoice_item_id | BH1: invoice_items.description | BI1: invoice_items.amount | BJ1: payment_id | BK1: payment_date | BL1: payment_method | BM1: payments.amount
A2: 1 | B2: Liam Smith | C2: Male | D2: 31149 | E2: 555-0101 | F2: liam.smith@example.com | G2: 123 Maple St, Springfield | H2: 46033.791 | I2: 1 | J2: Emergency | K2: 45996.433 | L2: 1 | M2: Attending | N2: 45996.438 | O2: 1 | P2: Liam Smith | Q2: Cardiologist | R2: 555-1001 | S2: liam.smith@hospital.com | T2: 1 | U2: 45296.396 | V2: Cardiology | W2: Deals with heart-related conditions and treatments. | X2: 1 | Y2: Monday | Z2: 0.33333333 | AA2: 0.58333333 | AB2: 0 | AC2: 1 | AD2: 45667.417 | AE2: complete | AF2: 1 | AG2: 45667.438 | AH2: Patient complained of chest pain. ECG advised. | AI2: 1 | AJ2: Hypertension | AK2: 1 | AL2: 45667.458 | AM2: 1 | AN2: 1 | AO2: ECG | AP2: 550 | AQ2: 1 | AR2: Normal ECG, no abnormalities detected | AS2: 45667 | AT2: 1 | AU2: Paracetamol | AV2: Acetaminophen 500mg | AW2: 500mg twice daily | AX2: 5 days | AY2: 12.5 | AZ2: 1 | BA2: Calpol | BB2: Acetaminophen 500mg | BC2: 10 | BD2: 1 | BE2: 45677 | BF2: 3500 | BG2: 1 | BH2: Doctor Consultation Fee | BI2: 500 | BJ2: 1 | BK2: 45678 | BL2: Cash | BM2: 3500
A3: 1 | B3: Liam Smith | C3: Male | D3: 31149 | E3: 555-0101 | F3: liam.smith@example.com | G3: 123 Maple St, Springfield | H3: 46033.791 | I3: 1 | J3: Emergency | K3: 45996.433 | L3: 1 | M3: Attending | N3: 45996.438 | O3: 1 | P3: Liam Smith | Q3: Cardiologist | R3: 555-1001 | S3: liam.smith@hospital.com | T3: 1 | U3: 45296.396 | V3: Cardiology | W3: Deals with heart-related conditions and treatments. | X3: 2 | Y3: Wednesday | Z3: 0.41666667 | AA3: 0.66666667 | AB3: 1 | AC3: 1 | AD3: 45667.417 | AE3: complete | AF3: 1 | AG3: 45667.438 | AH3: Patient complained of chest pain. ECG advised. | AI3: 1 | AJ3: Hypertension | AK3: 1 | AL3: 45667.458 | AM3: 1 | AN3: 1 | AO3: ECG | AP3: 550 | AQ3: 1 | AR3: Normal ECG, no abnormalities detected | AS3: 45667 | AT3: 1 | AU3: Paracetamol | AV3: Acetaminophen 500mg | AW3: 500mg twice daily | AX3: 5 days | AY3: 12.5 | AZ3: 1 | BA3: Calpol | BB3: Acetaminophen 500mg | BC3: 10 | BD3: 1 | BE3: 45677 | BF3: 3500 | BG3: 1 | BH3: Doctor Consultation Fee | BI3: 500 | BJ3: 1 | BK3: 45678 | BL3: Cash | BM3: 3500
A4: 1 | B4: Liam Smith | C4: Male | D4: 31149 | E4: 555-0101 | F4: liam.smith@example.com | G4: 123 Maple St, Springfield | H4: 46033.791 | I4: 1 | J4: Emergency | K4: 45996.433 | L4: 1 | M4: Attending | N4: 45996.438 | O4: 1 | P4: Liam Smith | Q4: Cardiologist | R4: 555-1001 | S4: liam.smith@hospital.com | T4: 1 | U4: 45296.396 | V4: Cardiology | W4: Deals with heart-related conditions and treatments. | X4: 3 | Y4: Friday | Z4: 0.375 | AA4: 0.625 | AB4: 0 | AC4: 1 | AD4: 45667.417 | AE4: complete | AF4: 1 | AG4: 45667.438 | AH4: Patient complained of chest pain. ECG advised. | AI4: 1 | AJ4: Hypertension | AK4: 1 | AL4: 45667.458 | AM4: 1 | AN4: 1 | AO4: ECG | AP4: 550 | AQ4: 1 | AR4: Normal ECG, no abnormalities detected | AS4: 45667 | AT4: 1 | AU4: Paracetamol | AV4: Acetaminophen 500mg | AW4: 500mg twice daily | AX4: 5 days | AY4: 12.5 | AZ4: 1 | BA4: Calpol | BB4: Acetaminophen 500mg | BC4: 10 | BD4: 1 | BE4: 45677 | BF4: 3500 | BG4: 1 | BH4: Doctor Consultation Fee | BI4: 500 | BJ4: 1 | BK4: 45678 | BL4: Cash | BM4: 3500
A5: 1 | B5: Liam Smith | C5: Male | D5: 31149 | E5: 555-0101 | F5: liam.smith@example.com | G5: 123 Maple St, Springfield | H5: 46033.791 | I5: 1 | J5: Emergency | K5: 45996.433 | L5: 1 | M5: Attending | N5: 45996.438 | O5: 1 | P5: Liam Smith | Q5: Cardiologist | R5: 555-1001 | S5: liam.smith@hospital.com | T5: 1 | U5: 45296.396 | V5: Cardiology | W5: Deals with heart-related conditions and treatments. | X5: 1 | Y5: Monday | Z5: 0.33333333 | AA5: 0.58333333 | AB5: 0 | AC5: 1 | AD5: 45667.417 | AE5: complete | AF5: 1 | AG5: 45667.438 | AH5: Patient complained of chest pain. ECG advised. | AI5: 1 | AJ5: Hypertension | AK5: 1 | AL5: 45667.458 | AM5: 1 | AN5: 1 | AO5: ECG | AP5: 550 | AQ5: 1 | AR5: Normal ECG, no abnormalities detected | AS5: 45667 | AT5: 1 | AU5: Paracetamol | AV5: Acetaminophen 500mg | AW5: 500mg twice daily | AX5: 5 days | AY5: 12.5 | AZ5: 1 | BA5: Calpol | BB5: Acetaminophen 500mg | BC5: 10 | BD5: 1 | BE5: 45677 | BF5: 3500 | BG5: 2 | BH5: ECG Test | BI5: 500 | BJ5: 1 | BK5: 45678 | BL5: Cash | BM5: 3500
A6: 1 | B6: Liam Smith | C6: Male | D6: 31149 | E6: 555-0101 | F6: liam.smith@example.com | G6: 123 Maple St, Springfield | H6: 46033.791 | I6: 1 | J6: Emergency | K6: 45996.433 | L6: 1 | M6: Attending | N6: 45996.438 | O6: 1 | P6: Liam Smith | Q6: Cardiologist | R6: 555-1001 | S6: liam.smith@hospital.com | T6: 1 | U6: 45296.396 | V6: Cardiology | W6: Deals with heart-related conditions and treatments. | X6: 2 | Y6: Wednesday | Z6: 0.41666667 | AA6: 0.66666667 | AB6: 1 | AC6: 1 | AD6: 45667.417 | AE6: complete | AF6: 1 | AG6: 45667.438 | AH6: Patient complained of chest pain. ECG advised. | AI6: 1 | AJ6: Hypertension | AK6: 1 | AL6: 45667.458 | AM6: 1 | AN6: 1 | AO6: ECG | AP6: 550 | AQ6: 1 | AR6: Normal ECG, no abnormalities detected | AS6: 45667 | AT6: 1 | AU6: Paracetamol | AV6: Acetaminophen 500mg | AW6: 500mg twice daily | AX6: 5 days | AY6: 12.5 | AZ6: 1 | BA6: Calpol | BB6: Acetaminophen 500mg | BC6: 10 | BD6: 1 | BE6: 45677 | BF6: 3500 | BG6: 2 | BH6: ECG Test | BI6: 500 | BJ6: 1 | BK6: 45678 | BL6: Cash | BM6: 3500
A7: 1 | B7: Liam Smith | C7: Male | D7: 31149 | E7: 555-0101 | F7: liam.smith@example.com | G7: 123 Maple St, Springfield | H7: 46033.791 | I7: 1 | J7: Emergency | K7: 45996.433 | L7: 1 | M7: Attending | N7: 45996.438 | O7: 1 | P7: Liam Smith | Q7: Cardiologist | R7: 555-1001 | S7: liam.smith@hospital.com | T7: 1 | U7: 45296.396 | V7: Cardiology | W7: Deals with heart-related conditions and treatments. | X7: 3 | Y7: Friday | Z7: 0.375 | AA7: 0.625 | AB7: 0 | AC7: 1 | AD7: 45667.417 | AE7: complete | AF7: 1 | AG7: 45667.438 | AH7: Patient complained of chest pain. ECG advised. | AI7: 1 | AJ7: Hypertension | AK7: 1 | AL7: 45667.458 | AM7: 1 | AN7: 1 | AO7: ECG | AP7: 550 | AQ7: 1 | AR7: Normal ECG, no abnormalities detected | AS7: 45667 | AT7: 1 | AU7: Paracetamol | AV7: Acetaminophen 500mg | AW7: 500mg twice daily | AX7: 5 days | AY7: 12.5 | AZ7: 1 | BA7: Calpol | BB7: Acetaminophen 500mg | BC7: 10 | BD7: 1 | BE7: 45677 | BF7: 3500 | BG7: 2 | BH7: ECG Test | BI7: 500 | BJ7: 1 | BK7: 45678 | BL7: Cash | BM7: 3500
A8: 1 | B8: Liam Smith | C8: Male | D8: 31149 | E8: 555-0101 | F8: liam.smith@example.com | G8: 123 Maple St, Springfield | H8: 46033.791 | I8: 1 | J8: Emergency | K8: 45996.433 | L8: 1 | M8: Attending | N8: 45996.438 | O8: 1 | P8: Liam Smith | Q8: Cardiologist | R8: 555-1001 | S8: liam.smith@hospital.com | T8: 1 | U8: 45296.396 | V8: Cardiology | W8: Deals with heart-related conditions and treatments. | X8: 1 | Y8: Monday | Z8: 0.33333333 | AA8: 0.58333333 | AB8: 0 | AC8: 1 | AD8: 45667.417 | AE8: complete | AF8: 1 | AG8: 45667.438 | AH8: Patient complained of chest pain. ECG advised. | AI8: 1 | AJ8: Hypertension | AK8: 1 | AL8: 45667.458 | AM8: 1 | AN8: 1 | AO8: ECG | AP8: 550 | AQ8: 1 | AR8: Normal ECG, no abnormalities detected | AS8: 45667 | AT8: 1 | AU8: Paracetamol | AV8: Acetaminophen 500mg | AW8: 500mg twice daily | AX8: 5 days | AY8: 12.5 | AZ8: 1 | BA8: Calpol | BB8: Acetaminophen 500mg | BC8: 10 | BD8: 1 | BE8: 45677 | BF8: 3500 | BG8: 3 | BH8: Medicines | BI8: 2500 | BJ8: 1 | BK8: 45678 | BL8: Cash | BM8: 3500
A9: 1 | B9: Liam Smith | C9: Male | D9: 31149 | E9: 555-0101 | F9: liam.smith@example.com | G9: 123 Maple St, Springfield | H9: 46033.791 | I9: 1 | J9: Emergency | K9: 45996.433 | L9: 1 | M9: Attending | N9: 45996.438 | O9: 1 | P9: Liam Smith | Q9: Cardiologist | R9: 555-1001 | S9: liam.smith@hospital.com | T9: 1 | U9: 45296.396 | V9: Cardiology | W9: Deals with heart-related conditions and treatments. | X9: 2 | Y9: Wednesday | Z9: 0.41666667 | AA9: 0.66666667 | AB9: 1 | AC9: 1 | AD9: 45667.417 | AE9: complete | AF9: 1 | AG9: 45667.438 | AH9: Patient complained of chest pain. ECG advised. | AI9: 1 | AJ9: Hypertension | AK9: 1 | AL9: 45667.458 | AM9: 1 | AN9: 1 | AO9: ECG | AP9: 550 | AQ9: 1 | AR9: Normal ECG, no abnormalities detected | AS9: 45667 | AT9: 1 | AU9: Paracetamol | AV9: Acetaminophen 500mg | AW9: 500mg twice daily | AX9: 5 days | AY9: 12.5 | AZ9: 1 | BA9: Calpol | BB9: Acetaminophen 500mg | BC9: 10 | BD9: 1 | BE9: 45677 | BF9: 3500 | BG9: 3 | BH9: Medicines | BI9: 2500 | BJ9: 1 | BK9: 45678 | BL9: Cash | BM9: 3500
A10: 1 | B10: Liam Smith | C10: Male | D10: 31149 | E10: 555-0101 | F10: liam.smith@example.com | G10: 123 Maple St, Springfield | H10: 46033.791 | I10: 1 | J10: Emergency | K10: 45996.433 | L10: 1 | M10: Attending | N10: 45996.438 | O10: 1 | P10: Liam Smith | Q10: Cardiologist | R10: 555-1001 | S10: liam.smith@hospital.com | T10: 1 | U10: 45296.396 | V10: Cardiology | W10: Deals with heart-related conditions and treatments. | X10: 3 | Y10: Friday | Z10: 0.375 | AA10: 0.625 | AB10: 0 | AC10: 1 | AD10: 45667.417 | AE10: complete | AF10: 1 | AG10: 45667.438 | AH10: Patient complained of chest pain. ECG advised. | AI10: 1 | AJ10: Hypertension | AK10: 1 | AL10: 45667.458 | AM10: 1 | AN10: 1 | AO10: ECG | AP10: 550 | AQ10: 1 | AR10: Normal ECG, no abnormalities detected | AS10: 45667 | AT10: 1 | AU10: Paracetamol | AV10: Acetaminophen 500mg | AW10: 500mg twice daily | AX10: 5 days | AY10: 12.5 | AZ10: 1 | BA10: Calpol | BB10: Acetaminophen 500mg | BC10: 10 | BD10: 1 | BE10: 45677 | BF10: 3500 | BG10: 3 | BH10: Medicines | BI10: 2500 | BJ10: 1 | BK10: 45678 | BL10: Cash | BM10: 3500
A11: 1 | B11: Liam Smith | C11: Male | D11: 31149 | E11: 555-0101 | F11: liam.smith@example.com | G11: 123 Maple St, Springfield | H11: 46033.791 | I11: 1 | J11: Emergency | K11: 45996.433 | L11: 1 | M11: Attending | N11: 45996.438 | O11: 1 | P11: Liam Smith | Q11: Cardiologist | R11: 555-1001 | S11: liam.smith@hospital.com | T11: 1 | U11: 45296.396 | V11: Cardiology | W11: Deals with heart-related conditions and treatments. | X11: 1 | Y11: Monday | Z11: 0.33333333 | AA11: 0.58333333 | AB11: 0 | AC11: 1 | AD11: 45667.417 | AE11: complete | AF11: 1 | AG11: 45667.438 | AH11: Patient complained of chest pain. ECG advised. | AI11: 2 | AJ11: Chest Pain - Suspected Angina | AK11: 1 | AL11: 45667.458 | AM11: 1 | AN11: 1 | AO11: ECG | AP11: 550 | AQ11: 1 | AR11: Normal ECG, no abnormalities detected | AS11: 45667 | AT11: 1 | AU11: Paracetamol | AV11: Acetaminophen 500mg | AW11: 500mg twice daily | AX11: 5 days | AY11: 12.5 | AZ11: 1 | BA11: Calpol | BB11: Acetaminophen 500mg | BC11: 10 | BD11: 1 | BE11: 45677 | BF11: 3500 | BG11: 1 | BH11: Doctor Consultation Fee | BI11: 500 | BJ11: 1 | BK11: 45678 | BL11: Cash | BM11: 3500
A12: 1 | B12: Liam Smith | C12: Male | D12: 31149 | E12: 555-0101 | F12: liam.smith@example.com | G12: 123 Maple St, Springfield | H12: 46033.791 | I12: 1 | J12: Emergency | K12: 45996.433 | L12: 1 | M12: Attending | N12: 45996.438 | O12: 1 | P12: Liam Smith | Q12: Cardiologist | R12: 555-1001 | S12: liam.smith@hospital.com | T12: 1 | U12: 45296.396 | V12: Cardiology | W12: Deals with heart-related conditions and treatments. | X12: 2 | Y12: Wednesday | Z12: 0.41666667 | AA12: 0.66666667 | AB12: 1 | AC12: 1 | AD12: 45667.417 | AE12: complete | AF12: 1 | AG12: 45667.438 | AH12: Patient complained of chest pain. ECG advised. | AI12: 2 | AJ12: Chest Pain - Suspected Angina | AK12: 1 | AL12: 45667.458 | AM12: 1 | AN12: 1 | AO12: ECG | AP12: 550 | AQ12: 1 | AR12: Normal ECG, no abnormalities detected | AS12: 45667 | AT12: 1 | AU12: Paracetamol | AV12: Acetaminophen 500mg | AW12: 500mg twice daily | AX12: 5 days | AY12: 12.5 | AZ12: 1 | BA12: Calpol | BB12: Acetaminophen 500mg | BC12: 10 | BD12: 1 | BE12: 45677 | BF12: 3500 | BG12: 1 | BH12: Doctor Consultation Fee | BI12: 500 | BJ12: 1 | BK12: 45678 | BL12: Cash | BM12: 3500
A13: 1 | B13: Liam Smith | C13: Male | D13: 31149 | E13: 555-0101 | F13: liam.smith@example.com | G13: 123 Maple St, Springfield | H13: 46033.791 | I13: 1 | J13: Emergency | K13: 45996.433 | L13: 1 | M13: Attending | N13: 45996.438 | O13: 1 | P13: Liam Smith | Q13: Cardiologist | R13: 555-1001 | S13: liam.smith@hospital.com | T13: 1 | U13: 45296.396 | V13: Cardiology | W13: Deals with heart-related conditions and treatments. | X13: 3 | Y13: Friday | Z13: 0.375 | AA13: 0.625 | AB13: 0 | AC13: 1 | AD13: 45667.417 | AE13: complete | AF13: 1 | AG13: 45667.438 | AH13: Patient complained of chest pain. ECG advised. | AI13: 2 | AJ13: Chest Pain - Suspected Angina | AK13: 1 | AL13: 45667.458 | AM13: 1 | AN13: 1 | AO13: ECG | AP13: 550 | AQ13: 1 | AR13: Normal ECG, no abnormalities detected | AS13: 45667 | AT13: 1 | AU13: Paracetamol | AV13: Acetaminophen 500mg | AW13: 500mg twice daily | AX13: 5 days | AY13: 12.5 | AZ13: 1 | BA13: Calpol | BB13: Acetaminophen 500mg | BC13: 10 | BD13: 1 | BE13: 45677 | BF13: 3500 | BG13: 1 | BH13: Doctor Consultation Fee | BI13: 500 | BJ13: 1 | BK13: 45678 | BL13: Cash | BM13: 3500
... A163: 2 | B163: Olivia Johnson | C163: Female | D163: 33107 | E163: 555-0102 | F163: olivia.johnson@example.com | G163: 456 Oak St, Springfield | H163: 46033.791 | I163: 2 | J163: Normal | K163: 45981.615 | L163: 3 | M163: Attending | N163: 45981.622 | O163: 2 | P163: Olivia Johnson | Q163: Neurologist | R163: 555-1002 | S163: olivia.johnson@hospital.com | T163: 2 | U163: 45332.427 | V163: Neurology | W163: Focuses on disorders of the nervous system and brain. | X163: 6 | Y163: Saturday | Z163: 0.41666667 | AA163: 0.58333333 | AB163: 1 | AC163: 2 | AD163: 45668.479 | AE163: complete | AF163: 2 | AG163: 45668.5 | AH163: Follow-up visit. Blood pressure stable. | AI163: 3 | AJ163: Essential Hypertension | AK163: 2 | AL163: 45668.521 | AM163: 4 | AN163: 4 | AO163: Blood Sugar Test | AP163: 300 | AQ163: 2 | AR163: Cholesterol slightly elevated, LDL 140 mg/dL | AS163: 45668 | AT163: 9 | AU163: Atorvastatin | AV163: Atorvastatin 10mg | AW163: 10mg once daily | AX163: 30 days | AY163: 32 | AZ163: 9 | BA163: Lipitor | BB163: Atorvastatin 10mg | BC163: 30 | BD163: 2 | BE163: 45678 | BF163: 4200 | BG163: 6 | BH163: Medicines | BI163: 2600 | BJ163: 2 | BK163: 45680 | BL163: Card | BM163: 4200
A164: 3 | B164: Noah Williams | C164: Male | D164: 28495 | E164: 555-0103 | F164: noah.williams@example.com | G164: 789 Pine St, Springfield | H164: 46033.791 | I164: 3 | J164: Accident | K164: 45945.396 | L164: 4 | M164: Attending | N164: 45945.406 | O164: 3 | P164: Noah Williams | Q164: Orthopedic Surgeon | R164: 555-1003 | S164: noah.williams@hospital.com | T164: 3 | U164: 45363.49 | V164: Orthopedics | W164: Handles musculoskeletal issues, bones, joints, and ligaments. | X164: 7 | Y164: Monday | Z164: 0.33333333 | AA164: 0.5 | AB164: 0 | AF164: 3 | AG164: 45669.406 | AH164: Minor injuries due to accident. X-ray suggested. | AI164: 4 | AJ164: Migraine | AK164: 3 | AL164: 45669.427 | AM164: 5 | AN164: 5 | AO164: Ultrasound Abdomen | AP164: 1500 | AQ164: 3 | AR164: Chest X-Ray normal, no fractures | AS164: 45669 | AT164: 31 | AU164: Diclofenac | AV164: Diclofenac Sodium 50mg | AW164: 50mg twice daily | AX164: 5 days | AY164: 22 | AZ164: 22 | BA164: Voveran | BB164: Diclofenac Sodium 50mg | BC164: 20 | BD164: 3 | BE164: 45679 | BF164: 1800 | BG164: 7 | BH164: Doctor Consultation Fee | BI164: 400 | BJ164: 3 | BK164: 45680 | BL164: UPI | BM164: 1800
A165: 3 | B165: Noah Williams | C165: Male | D165: 28495 | E165: 555-0103 | F165: noah.williams@example.com | G165: 789 Pine St, Springfield | H165: 46033.791 | I165: 3 | J165: Accident | K165: 45945.396 | L165: 4 | M165: Attending | N165: 45945.406 | O165: 3 | P165: Noah Williams | Q165: Orthopedic Surgeon | R165: 555-1003 | S165: noah.williams@hospital.com | T165: 3 | U165: 45363.49 | V165: Orthopedics | W165: Handles musculoskeletal issues, bones, joints, and ligaments. | X165: 8 | Y165: Wednesday | Z165: 0.54166667 | AA165: 0.70833333 | AB165: 0 | AF165: 3 | AG165: 45669.406 | AH165: Minor injuries due to accident. X-ray suggested. | AI165: 4 | AJ165: Migraine | AK165: 3 | AL165: 45669.427 | AM165: 5 | AN165: 5 | AO165: Ultrasound Abdomen | AP165: 1500 | AQ165: 3 | AR165: Chest X-Ray normal, no fractures | AS165: 45669 | AT165: 31 | AU165: Diclofenac | AV165: Diclofenac Sodium 50mg | AW165: 50mg twice daily | AX165: 5 days | AY165: 22 | AZ165: 22 | BA165: Voveran | BB165: Diclofenac Sodium 50mg | BC165: 20 | BD165: 3 | BE165: 45679 | BF165: 1800 | BG165: 7 | BH165: Doctor Consultation Fee | BI165: 400 | BJ165: 3 | BK165: 45680 | BL165: UPI | BM165: 1800
A166: 3 | B166: Noah Williams | C166: Male | D166: 28495 | E166: 555-0103 | F166: noah.williams@example.com | G166: 789 Pine St, Springfield | H166: 46033.791 | I166: 3 | J166: Accident | K166: 45945.396 | L166: 4 | M166: Attending | N166: 45945.406 | O166: 3 | P166: Noah Williams | Q166: Orthopedic Surgeon | R166: 555-1003 | S166: noah.williams@hospital.com | T166: 3 | U166: 45363.49 | V166: Orthopedics | W166: Handles musculoskeletal issues, bones, joints, and ligaments. | X166: 9 | Y166: Friday | Z166: 0.375 | AA166: 0.625 | AB166: 1 | AF166: 3 | AG166: 45669.406 | AH166: Minor injuries due to accident. X-ray suggested. | AI166: 4 | AJ166: Migraine | AK166: 3 | AL166: 45669.427 | AM166: 5 | AN166: 5 | AO166: Ultrasound Abdomen | AP166: 1500 | AQ166: 3 | AR166: Chest X-Ray normal, no fractures | AS166: 45669 | AT166: 31 | AU166: Diclofenac | AV166: Diclofenac Sodium 50mg | AW166: 50mg twice daily | AX166: 5 days | AY166: 22 | AZ166: 22 | BA166: Voveran | BB166: Diclofenac Sodium 50mg | BC166: 20 | BD166: 3 | BE166: 45679 | BF166: 1800 | BG166: 7 | BH166: Doctor Consultation Fee | BI166: 400 | BJ166: 3 | BK166: 45680 | BL166: UPI | BM166: 1800
A167: 3 | B167: Noah Williams | C167: Male | D167: 28495 | E167: 555-0103 | F167: noah.williams@example.com | G167: 789 Pine St, Springfield | H167: 46033.791 | I167: 3 | J167: Accident | K167: 45945.396 | L167: 4 | M167: Attending | N167: 45945.406 | O167: 3 | P167: Noah Williams | Q167: Orthopedic Surgeon | R167: 555-1003 | S167: noah.williams@hospital.com | T167: 3 | U167: 45363.49 | V167: Orthopedics | W167: Handles musculoskeletal issues, bones, joints, and ligaments. | X167: 7 | Y167: Monday | Z167: 0.33333333 | AA167: 0.5 | AB167: 0 | AF167: 3 | AG167: 45669.406 | AH167: Minor injuries due to accident. X-ray suggested. | AI167: 4 | AJ167: Migraine | AK167: 3 | AL167: 45669.427 | AM167: 5 | AN167: 5 | AO167: Ultrasound Abdomen | AP167: 1500 | AQ167: 3 | AR167: Chest X-Ray normal, no fractures | AS167: 45669 | AT167: 31 | AU167: Diclofenac | AV167: Diclofenac Sodium 50mg | AW167: 50mg twice daily | AX167: 5 days | AY167: 22 | AZ167: 22 | BA167: Voveran | BB167: Diclofenac Sodium 50mg | BC167: 20 | BD167: 3 | BE167: 45679 | BF167: 1800 | BG167: 8 | BH167: Chest X-Ray | BI167: 800 | BJ167: 3 | BK167: 45680 | BL167: UPI | BM167: 1800
A168: 3 | B168: Noah Williams | C168: Male | D168: 28495 | E168: 555-0103 | F168: noah.williams@example.com | G168: 789 Pine St, Springfield | H168: 46033.791 | I168: 3 | J168: Accident | K168: 45945.396 | L168: 4 | M168: Attending | N168: 45945.406 | O168: 3 | P168: Noah Williams | Q168: Orthopedic Surgeon | R168: 555-1003 | S168: noah.williams@hospital.com | T168: 3 | U168: 45363.49 | V168: Orthopedics | W168: Handles musculoskeletal issues, bones, joints, and ligaments. | X168: 8 | Y168: Wednesday | Z168: 0.54166667 | AA168: 0.70833333 | AB168: 0 | AF168: 3 | AG168: 45669.406 | AH168: Minor injuries due to accident. X-ray suggested. | AI168: 4 | AJ168: Migraine | AK168: 3 | AL168: 45669.427 | AM168: 5 | AN168: 5 | AO168: Ultrasound Abdomen | AP168: 1500 | AQ168: 3 | AR168: Chest X-Ray normal, no fractures | AS168: 45669 | AT168: 31 | AU168: Diclofenac | AV168: Diclofenac Sodium 50mg | AW168: 50mg twice daily | AX168: 5 days | AY168: 22 | AZ168: 22 | BA168: Voveran | BB168: Diclofenac Sodium 50mg | BC168: 20 | BD168: 3 | BE168: 45679 | BF168: 1800 | BG168: 8 | BH168: Chest X-Ray | BI168: 800 | BJ168: 3 | BK168: 45680 | BL168: UPI | BM168: 1800
A169: 3 | B169: Noah Williams | C169: Male | D169: 28495 | E169: 555-0103 | F169: noah.williams@example.com | G169: 789 Pine St, Springfield | H169: 46033.791 | I169: 3 | J169: Accident | K169: 45945.396 | L169: 4 | M169: Attending | N169: 45945.406 | O169: 3 | P169: Noah Williams | Q169: Orthopedic Surgeon | R169: 555-1003 | S169: noah.williams@hospital.com | T169: 3 | U169: 45363.49 | V169: Orthopedics | W169: Handles musculoskeletal issues, bones, joints, and ligaments. | X169: 9 | Y169: Friday | Z169: 0.375 | AA169: 0.625 | AB169: 1 | AF169: 3 | AG169: 45669.406 | AH169: Minor injuries due to accident. X-ray suggested. | AI169: 4 | AJ169: Migraine | AK169: 3 | AL169: 45669.427 | AM169: 5 | AN169: 5 | AO169: Ultrasound Abdomen | AP169: 1500 | AQ169: 3 | AR169: Chest X-Ray normal, no fractures | AS169: 45669 | AT169: 31 | AU169: Diclofenac | AV169: Diclofenac Sodium 50mg | AW169: 50mg twice daily | AX169: 5 days | AY169: 22 | AZ169: 22 | BA169: Voveran | BB169: Diclofenac Sodium 50mg | BC169: 20 | BD169: 3 | BE169: 45679 | BF169: 1800 | BG169: 8 | BH169: Chest X-Ray | BI169: 800 | BJ169: 3 | BK169: 45680 | BL169: UPI | BM169: 1800
A170: 3 | B170: Noah Williams | C170: Male | D170: 28495 | E170: 555-0103 | F170: noah.williams@example.com | G170: 789 Pine St, Springfield | H170: 46033.791 | I170: 3 | J170: Accident | K170: 45945.396 | L170: 4 | M170: Attending | N170: 45945.406 | O170: 3 | P170: Noah Williams | Q170: Orthopedic Surgeon | R170: 555-1003 | S170: noah.williams@hospital.com | T170: 3 | U170: 45363.49 | V170: Orthopedics | W170: Handles musculoskeletal issues, bones, joints, and ligaments. | X170: 7 | Y170: Monday | Z170: 0.33333333 | AA170: 0.5 | AB170: 0 | AF170: 3 | AG170: 45669.406 | AH170: Minor injuries due to accident. X-ray suggested. | AI170: 4 | AJ170: Migraine | AK170: 3 | AL170: 45669.427 | AM170: 5 | AN170: 5 | AO170: Ultrasound Abdomen | AP170: 1500 | AQ170: 3 | AR170: Chest X-Ray normal, no fractures | AS170: 45669 | AT170: 31 | AU170: Diclofenac | AV170: Diclofenac Sodium 50mg | AW170: 50mg twice daily | AX170: 5 days | AY170: 22 | AZ170: 22 | BA170: Voveran | BB170: Diclofenac Sodium 50mg | BC170: 20 | BD170: 3 | BE170: 45679 | BF170: 1800 | BG170: 9 | BH170: Medicines | BI170: 600 | BJ170: 3 | BK170: 45680 | BL170: UPI | BM170: 1800
A171: 3 | B171: Noah Williams | C171: Male | D171: 28495 | E171: 555-0103 | F171: noah.williams@example.com | G171: 789 Pine St, Springfield | H171: 46033.791 | I171: 3 | J171: Accident | K171: 45945.396 | L171: 4 | M171: Attending | N171: 45945.406 | O171: 3 | P171: Noah Williams | Q171: Orthopedic Surgeon | R171: 555-1003 | S171: noah.williams@hospital.com | T171: 3 | U171: 45363.49 | V171: Orthopedics | W171: Handles musculoskeletal issues, bones, joints, and ligaments. | X171: 8 | Y171: Wednesday | Z171: 0.54166667 | AA171: 0.70833333 | AB171: 0 | AF171: 3 | AG171: 45669.406 | AH171: Minor injuries due to accident. X-ray suggested. | AI171: 4 | AJ171: Migraine | AK171: 3 | AL171: 45669.427 | AM171: 5 | AN171: 5 | AO171: Ultrasound Abdomen | AP171: 1500 | AQ171: 3 | AR171: Chest X-Ray normal, no fractures | AS171: 45669 | AT171: 31 | AU171: Diclofenac | AV171: Diclofenac Sodium 50mg | AW171: 50mg twice daily | AX171: 5 days | AY171: 22 | AZ171: 22 | BA171: Voveran | BB171: Diclofenac Sodium 50mg | BC171: 20 | BD171: 3 | BE171: 45679 | BF171: 1800 | BG171: 9 | BH171: Medicines | BI171: 600 | BJ171: 3 | BK171: 45680 | BL171: UPI | BM171: 1800
A172: 3 | B172: Noah Williams | C172: Male | D172: 28495 | E172: 555-0103 | F172: noah.williams@example.com | G172: 789 Pine St, Springfield | H172: 46033.791 | I172: 3 | J172: Accident | K172: 45945.396 | L172: 4 | M172: Attending | N172: 45945.406 | O172: 3 | P172: Noah Williams | Q172: Orthopedic Surgeon | R172: 555-1003 | S172: noah.williams@hospital.com | T172: 3 | U172: 45363.49 | V172: Orthopedics | W172: Handles musculoskeletal issues, bones, joints, and ligaments. | X172: 9 | Y172: Friday | Z172: 0.375 | AA172: 0.625 | AB172: 1 | AF172: 3 | AG172: 45669.406 | AH172: Minor injuries due to accident. X-ray suggested. | AI172: 4 | AJ172: Migraine | AK172: 3 | AL172: 45669.427 | AM172: 5 | AN172: 5 | AO172: Ultrasound Abdomen | AP172: 1500 | AQ172: 3 | AR172: Chest X-Ray normal, no fractures | AS172: 45669 | AT172: 31 | AU172: Diclofenac | AV172: Diclofenac Sodium 50mg | AW172: 50mg twice daily | AX172: 5 days | AY172: 22 | AZ172: 22 | BA172: Voveran | BB172: Diclofenac Sodium 50mg | BC172: 20 | BD172: 3 | BE172: 45679 | BF172: 1800 | BG172: 9 | BH172: Medicines | BI172: 600 | BJ172: 3 | BK172: 45680 | BL172: UPI | BM172: 1800
A173: 3 | B173: Noah Williams | C173: Male | D173: 28495 | E173: 555-0103 | F173: noah.williams@example.com | G173: 789 Pine St, Springfield | H173: 46033.791 | I173: 3 | J173: Accident | K173: 45945.396 | L173: 4 | M173: Attending | N173: 45945.406 | O173: 3 | P173: Noah Williams | Q173: Orthopedic Surgeon | R173: 555-1003 | S173: noah.williams@hospital.com | T173: 3 | U173: 45363.49 | V173: Orthopedics | W173: Handles musculoskeletal issues, bones, joints, and ligaments. | X173: 7 | Y173: Monday | Z173: 0.33333333 | AA173: 0.5 | AB173: 0 | AF173: 3 | AG173: 45669.406 | AH173: Minor injuries due to accident. X-ray suggested. | AI173: 5 | AJ173: Minor Head Injury | AK173: 3 | AL173: 45669.427 | AM173: 5 | AN173: 5 | AO173: Ultrasound Abdomen | AP173: 1500 | AQ173: 3 | AR173: Chest X-Ray normal, no fractures | AS173: 45669 | AT173: 31 | AU173: Diclofenac | AV173: Diclofenac Sodium 50mg | AW173: 50mg twice daily | AX173: 5 days | AY173: 22 | AZ173: 22 | BA173: Voveran | BB173: Diclofenac Sodium 50mg | BC173: 20 | BD173: 3 | BE173: 45679 | BF173: 1800 | BG173: 7 | BH173: Doctor Consultation Fee | BI173: 400 | BJ173: 3 | BK173: 45680 | BL173: UPI | BM173: 1800
A174: 3 | B174: Noah Williams | C174: Male | D174: 28495 | E174: 555-0103 | F174: noah.williams@example.com | G174: 789 Pine St, Springfield | H174: 46033.791 | I174: 3 | J174: Accident | K174: 45945.396 | L174: 4 | M174: Attending | N174: 45945.406 | O174: 3 | P174: Noah Williams | Q174: Orthopedic Surgeon | R174: 555-1003 | S174: noah.williams@hospital.com | T174: 3 | U174: 45363.49 | V174: Orthopedics | W174: Handles musculoskeletal issues, bones, joints, and ligaments. | X174: 8 | Y174: Wednesday | Z174: 0.54166667 | AA174: 0.70833333 | AB174: 0 | AF174: 3 | AG174: 45669.406 | AH174: Minor injuries due to accident. X-ray suggested. | AI174: 5 | AJ174: Minor Head Injury | AK174: 3 | AL174: 45669.427 | AM174: 5 | AN174: 5 | AO174: Ultrasound Abdomen | AP174: 1500 | AQ174: 3 | AR174: Chest X-Ray normal, no fractures | AS174: 45669 | AT174: 31 | AU174: Diclofenac | AV174: Diclofenac Sodium 50mg | AW174: 50mg twice daily | AX174: 5 days | AY174: 22 | AZ174: 22 | BA174: Voveran | BB174: Diclofenac Sodium 50mg | BC174: 20 | BD174: 3 | BE174: 45679 | BF174: 1800 | BG174: 7 | BH174: Doctor Consultation Fee | BI174: 400 | BJ174: 3 | BK174: 45680 | BL174: UPI | BM174: 1800
A175: 3 | B175: Noah Williams | C175: Male | D175: 28495 | E175: 555-0103 | F175: noah.williams@example.com | G175: 789 Pine St, Springfield | H175: 46033.791 | I175: 3 | J175: Accident | K175: 45945.396 | L175: 4 | M175: Attending | N175: 45945.406 | O175: 3 | P175: Noah Williams | Q175: Orthopedic Surgeon | R175: 555-1003 | S175: noah.williams@hospital.com | T175: 3 | U175: 45363.49 | V175: Orthopedics | W175: Handles musculoskeletal issues, bones, joints, and ligaments. | X175: 9 | Y175: Friday | Z175: 0.375 | AA175: 0.625 | AB175: 1 | AF175: 3 | AG175: 45669.406 | AH175: Minor injuries due to accident. X-ray suggested. | AI175: 5 | AJ175: Minor Head Injury | AK175: 3 | AL175: 45669.427 | AM175: 5 | AN175: 5 | AO175: Ultrasound Abdomen | AP175: 1500 | AQ175: 3 | AR175: Chest X-Ray normal, no fractures | AS175: 45669 | AT175: 31 | AU175: Diclofenac | AV175: Diclofenac Sodium 50mg | AW175: 50mg twice daily | AX175: 5 days | AY175: 22 | AZ175: 22 | BA175: Voveran | BB175: Diclofenac Sodium 50mg | BC175: 20 | BD175: 3 | BE175: 45679 | BF175: 1800 | BG175: 7 | BH175: Doctor Consultation Fee | BI175: 400 | BJ175: 3 | BK175: 45680 | BL175: UPI | BM175: 1800
... A235: 3 | B235: Noah Williams | C235: Male | D235: 28495 | E235: 555-0103 | F235: noah.williams@example.com | G235: 789 Pine St, Springfield | H235: 46033.791 | I235: 3 | J235: Accident | K235: 45945.396 | L235: 5 | M235: Surgeon | N235: 45945.438 | O235: 12 | P235: Mia Lopez | Q235: Neurologist | R235: 555-1012 | S235: mia.lopez@hospital.com | T235: 2 | U235: 45344.438 | V235: Neurology | W235: Focuses on disorders of the nervous system and brain. | X235: 36 | Y235: Saturday | Z235: 0.41666667 | AA235: 0.58333333 | AB235: 1 | AF235: 3 | AG235: 45669.406 | AH235: Minor injuries due to accident. X-ray suggested. | AI235: 5 | AJ235: Minor Head Injury | AK235: 3 | AL235: 45669.427 | AM235: 6 | AN235: 6 | AO235: Complete Blood Count | AP235: 400 | AQ235: 3 | AR235: Chest X-Ray normal, no fractures | AS235: 45669 | AT235: 29 | AU235: Ondansetron | AV235: Ondansetron 4mg | AW235: 4mg once daily | AX235: 3 days | AY235: 20 | AZ235: 21 | BA235: Zofran | BB235: Ondansetron 4mg | BC235: 18 | BD235: 3 | BE235: 45679 | BF235: 1800 | BG235: 9 | BH235: Medicines | BI235: 600 | BJ235: 3 | BK235: 45680 | BL235: UPI | BM235: 1800
A236: 4 | B236: Emma Brown | C236: Female | D236: 32462 | E236: 555-0104 | F236: emma.brown@example.com | G236: 321 Elm St, Springfield | H236: 46033.791 | I236: 4 | J236: Labour | K236: 45912.302 | L236: 6 | M236: Attending | N236: 45912.312 | O236: 4 | P236: Emma Brown | Q236: Pediatrician | R236: 555-1004 | S236: emma.brown@hospital.com | T236: 4 | U236: 45390.368 | V236: Pediatrics | W236: Cares for infants, children, and adolescents. | X236: 10 | Y236: Tuesday | Z236: 0.33333333 | AA236: 0.58333333 | AB236: 0 | AC236: 4 | AD236: 45670.583 | AE236: complete | AF236: 4 | AG236: 45670.604 | AH236: Routine antenatal check-up. | AI236: 6 | AJ236: Normal Pregnancy | AK236: 4 | AL236: 45670.625 | AM236: 7 | AN236: 7 | AO236: Thyroid Function Test | AP236: 900 | AQ236: 4 | AR236: Fasting blood sugar 95 mg/dL | AS236: 45670 | AT236: 25 | AU236: Vitamin D3 | AV236: Cholecalciferol 60000IU | AW236: 60000IU once weekly | AX236: 8 weeks | AY236: 55 | AZ236: 19 | BA236: Uprise D3 | BB236: Cholecalciferol 60000IU | BC236: 50 | BD236: 4 | BE236: 45680 | BF236: 2500 | BG236: 10 | BH236: Doctor Consultation Fee | BI236: 500 | BJ236: 4 | BK236: 45682 | BL236: Insurance | BM236: 2500
A237: 4 | B237: Emma Brown | C237: Female | D237: 32462 | E237: 555-0104 | F237: emma.brown@example.com | G237: 321 Elm St, Springfield | H237: 46033.791 | I237: 4 | J237: Labour | K237: 45912.302 | L237: 6 | M237: Attending | N237: 45912.312 | O237: 4 | P237: Emma Brown | Q237: Pediatrician | R237: 555-1004 | S237: emma.brown@hospital.com | T237: 4 | U237: 45390.368 | V237: Pediatrics | W237: Cares for infants, children, and adolescents. | X237: 11 | Y237: Thursday | Z237: 0.375 | AA237: 0.625 | AB237: 0 | AC237: 4 | AD237: 45670.583 | AE237: complete | AF237: 4 | AG237: 45670.604 | AH237: Routine antenatal check-up. | AI237: 6 | AJ237: Normal Pregnancy | AK237: 4 | AL237: 45670.625 | AM237: 7 | AN237: 7 | AO237: Thyroid Function Test | AP237: 900 | AQ237: 4 | AR237: Fasting blood sugar 95 mg/dL | AS237: 45670 | AT237: 25 | AU237: Vitamin D3 | AV237: Cholecalciferol 60000IU | AW237: 60000IU once weekly | AX237: 8 weeks | AY237: 55 | AZ237: 19 | BA237: Uprise D3 | BB237: Cholecalciferol 60000IU | BC237: 50 | BD237: 4 | BE237: 45680 | BF237: 2500 | BG237: 10 | BH237: Doctor Consultation Fee | BI237: 500 | BJ237: 4 | BK237: 45682 | BL237: Insurance | BM237: 2500
A238: 4 | B238: Emma Brown | C238: Female | D238: 32462 | E238: 555-0104 | F238: emma.brown@example.com | G238: 321 Elm St, Springfield | H238: 46033.791 | I238: 4 | J238: Labour | K238: 45912.302 | L238: 6 | M238: Attending | N238: 45912.312 | O238: 4 | P238: Emma Brown | Q238: Pediatrician | R238: 555-1004 | S238: emma.brown@hospital.com | T238: 4 | U238: 45390.368 | V238: Pediatrics | W238: Cares for infants, children, and adolescents. | X238: 12 | Y238: Saturday | Z238: 0.41666667 | AA238: 0.66666667 | AB238: 1 | AC238: 4 | AD238: 45670.583 | AE238: complete | AF238: 4 | AG238: 45670.604 | AH238: Routine antenatal check-up. | AI238: 6 | AJ238: Normal Pregnancy | AK238: 4 | AL238: 45670.625 | AM238: 7 | AN238: 7 | AO238: Thyroid Function Test | AP238: 900 | AQ238: 4 | AR238: Fasting blood sugar 95 mg/dL | AS238: 45670 | AT238: 25 | AU238: Vitamin D3 | AV238: Cholecalciferol 60000IU | AW238: 60000IU once weekly | AX238: 8 weeks | AY238: 55 | AZ238: 19 | BA238: Uprise D3 | BB238: Cholecalciferol 60000IU | BC238: 50 | BD238: 4 | BE238: 45680 | BF238: 2500 | BG238: 10 | BH238: Doctor Consultation Fee | BI238: 500 | BJ238: 4 | BK238: 45682 | BL238: Insurance | BM238: 2500
A239: 4 | B239: Emma Brown | C239: Female | D239: 32462 | E239: 555-0104 | F239: emma.brown@example.com | G239: 321 Elm St, Springfield | H239: 46033.791 | I239: 4 | J239: Labour | K239: 45912.302 | L239: 6 | M239: Attending | N239: 45912.312 | O239: 4 | P239: Emma Brown | Q239: Pediatrician | R239: 555-1004 | S239: emma.brown@hospital.com | T239: 4 | U239: 45390.368 | V239: Pediatrics | W239: Cares for infants, children, and adolescents. | X239: 10 | Y239: Tuesday | Z239: 0.33333333 | AA239: 0.58333333 | AB239: 0 | AC239: 4 | AD239: 45670.583 | AE239: complete | AF239: 4 | AG239: 45670.604 | AH239: Routine antenatal check-up. | AI239: 6 | AJ239: Normal Pregnancy | AK239: 4 | AL239: 45670.625 | AM239: 7 | AN239: 7 | AO239: Thyroid Function Test | AP239: 900 | AQ239: 4 | AR239: Fasting blood sugar 95 mg/dL | AS239: 45670 | AT239: 25 | AU239: Vitamin D3 | AV239: Cholecalciferol 60000IU | AW239: 60000IU once weekly | AX239: 8 weeks | AY239: 55 | AZ239: 19 | BA239: Uprise D3 | BB239: Cholecalciferol 60000IU | BC239: 50 | BD239: 4 | BE239: 45680 | BF239: 2500 | BG239: 11 | BH239: Blood Sugar Test | BI239: 300 | BJ239: 4 | BK239: 45682 | BL239: Insurance | BM239: 2500
A240: 4 | B240: Emma Brown | C240: Female | D240: 32462 | E240: 555-0104 | F240: emma.brown@example.com | G240: 321 Elm St, Springfield | H240: 46033.791 | I240: 4 | J240: Labour | K240: 45912.302 | L240: 6 | M240: Attending | N240: 45912.312 | O240: 4 | P240: Emma Brown | Q240: Pediatrician | R240: 555-1004 | S240: emma.brown@hospital.com | T240: 4 | U240: 45390.368 | V240: Pediatrics | W240: Cares for infants, children, and adolescents. | X240: 11 | Y240: Thursday | Z240: 0.375 | AA240: 0.625 | AB240: 0 | AC240: 4 | AD240: 45670.583 | AE240: complete | AF240: 4 | AG240: 45670.604 | AH240: Routine antenatal check-up. | AI240: 6 | AJ240: Normal Pregnancy | AK240: 4 | AL240: 45670.625 | AM240: 7 | AN240: 7 | AO240: Thyroid Function Test | AP240: 900 | AQ240: 4 | AR240: Fasting blood sugar 95 mg/dL | AS240: 45670 | AT240: 25 | AU240: Vitamin D3 | AV240: Cholecalciferol 60000IU | AW240: 60000IU once weekly | AX240: 8 weeks | AY240: 55 | AZ240: 19 | BA240: Uprise D3 | BB240: Cholecalciferol 60000IU | BC240: 50 | BD240: 4 | BE240: 45680 | BF240: 2500 | BG240: 11 | BH240: Blood Sugar Test | BI240: 300 | BJ240: 4 | BK240: 45682 | BL240: Insurance | BM240: 2500
A241: 4 | B241: Emma Brown | C241: Female | D241: 32462 | E241: 555-0104 | F241: emma.brown@example.com | G241: 321 Elm St, Springfield | H241: 46033.791 | I241: 4 | J241: Labour | K241: 45912.302 | L241: 6 | M241: Attending | N241: 45912.312 | O241: 4 | P241: Emma Brown | Q241: Pediatrician | R241: 555-1004 | S241: emma.brown@hospital.com | T241: 4 | U241: 45390.368 | V241: Pediatrics | W241: Cares for infants, children, and adolescents. | X241: 12 | Y241: Saturday | Z241: 0.41666667 | AA241: 0.66666667 | AB241: 1 | AC241: 4 | AD241: 45670.583 | AE241: complete | AF241: 4 | AG241: 45670.604 | AH241: Routine antenatal check-up. | AI241: 6 | AJ241: Normal Pregnancy | AK241: 4 | AL241: 45670.625 | AM241: 7 | AN241: 7 | AO241: Thyroid Function Test | AP241: 900 | AQ241: 4 | AR241: Fasting blood sugar 95 mg/dL | AS241: 45670 | AT241: 25 | AU241: Vitamin D3 | AV241: Cholecalciferol 60000IU | AW241: 60000IU once weekly | AX241: 8 weeks | AY241: 55 | AZ241: 19 | BA241: Uprise D3 | BB241: Cholecalciferol 60000IU | BC241: 50 | BD241: 4 | BE241: 45680 | BF241: 2500 | BG241: 11 | BH241: Blood Sugar Test | BI241: 300 | BJ241: 4 | BK241: 45682 | BL241: Insurance | BM241: 2500
A242: 4 | B242: Emma Brown | C242: Female | D242: 32462 | E242: 555-0104 | F242: emma.brown@example.com | G242: 321 Elm St, Springfield | H242: 46033.791 | I242: 4 | J242: Labour | K242: 45912.302 | L242: 6 | M242: Attending | N242: 45912.312 | O242: 4 | P242: Emma Brown | Q242: Pediatrician | R242: 555-1004 | S242: emma.brown@hospital.com | T242: 4 | U242: 45390.368 | V242: Pediatrics | W242: Cares for infants, children, and adolescents. | X242: 10 | Y242: Tuesday | Z242: 0.33333333 | AA242: 0.58333333 | AB242: 0 | AC242: 4 | AD242: 45670.583 | AE242: complete | AF242: 4 | AG242: 45670.604 | AH242: Routine antenatal check-up. | AI242: 6 | AJ242: Normal Pregnancy | AK242: 4 | AL242: 45670.625 | AM242: 7 | AN242: 7 | AO242: Thyroid Function Test | AP242: 900 | AQ242: 4 | AR242: Fasting blood sugar 95 mg/dL | AS242: 45670 | AT242: 25 | AU242: Vitamin D3 | AV242: Cholecalciferol 60000IU | AW242: 60000IU once weekly | AX242: 8 weeks | AY242: 55 | AZ242: 19 | BA242: Uprise D3 | BB242: Cholecalciferol 60000IU | BC242: 50 | BD242: 4 | BE242: 45680 | BF242: 2500 | BG242: 12 | BH242: Medicines | BI242: 1700 | BJ242: 4 | BK242: 45682 | BL242: Insurance | BM242: 2500
A243: 4 | B243: Emma Brown | C243: Female | D243: 32462 | E243: 555-0104 | F243: emma.brown@example.com | G243: 321 Elm St, Springfield | H243: 46033.791 | I243: 4 | J243: Labour | K243: 45912.302 | L243: 6 | M243: Attending | N243: 45912.312 | O243: 4 | P243: Emma Brown | Q243: Pediatrician | R243: 555-1004 | S243: emma.brown@hospital.com | T243: 4 | U243: 45390.368 | V243: Pediatrics | W243: Cares for infants, children, and adolescents. | X243: 11 | Y243: Thursday | Z243: 0.375 | AA243: 0.625 | AB243: 0 | AC243: 4 | AD243: 45670.583 | AE243: complete | AF243: 4 | AG243: 45670.604 | AH243: Routine antenatal check-up. | AI243: 6 | AJ243: Normal Pregnancy | AK243: 4 | AL243: 45670.625 | AM243: 7 | AN243: 7 | AO243: Thyroid Function Test | AP243: 900 | AQ243: 4 | AR243: Fasting blood sugar 95 mg/dL | AS243: 45670 | AT243: 25 | AU243: Vitamin D3 | AV243: Cholecalciferol 60000IU | AW243: 60000IU once weekly | AX243: 8 weeks | AY243: 55 | AZ243: 19 | BA243: Uprise D3 | BB243: Cholecalciferol 60000IU | BC243: 50 | BD243: 4 | BE243: 45680 | BF243: 2500 | BG243: 12 | BH243: Medicines | BI243: 1700 | BJ243: 4 | BK243: 45682 | BL243: Insurance | BM243: 2500
A244: 4 | B244: Emma Brown | C244: Female | D244: 32462 | E244: 555-0104 | F244: emma.brown@example.com | G244: 321 Elm St, Springfield | H244: 46033.791 | I244: 4 | J244: Labour | K244: 45912.302 | L244: 6 | M244: Attending | N244: 45912.312 | O244: 4 | P244: Emma Brown | Q244: Pediatrician | R244: 555-1004 | S244: emma.brown@hospital.com | T244: 4 | U244: 45390.368 | V244: Pediatrics | W244: Cares for infants, children, and adolescents. | X244: 12 | Y244: Saturday | Z244: 0.41666667 | AA244: 0.66666667 | AB244: 1 | AC244: 4 | AD244: 45670.583 | AE244: complete | AF244: 4 | AG244: 45670.604 | AH244: Routine antenatal check-up. | AI244: 6 | AJ244: Normal Pregnancy | AK244: 4 | AL244: 45670.625 | AM244: 7 | AN244: 7 | AO244: Thyroid Function Test | AP244: 900 | AQ244: 4 | AR244: Fasting blood sugar 95 mg/dL | AS244: 45670 | AT244: 25 | AU244: Vitamin D3 | AV244: Cholecalciferol 60000IU | AW244: 60000IU once weekly | AX244: 8 weeks | AY244: 55 | AZ244: 19 | BA244: Uprise D3 | BB244: Cholecalciferol 60000IU | BC244: 50 | BD244: 4 | BE244: 45680 | BF244: 2500 | BG244: 12 | BH244: Medicines | BI244: 1700 | BJ244: 4 | BK244: 45682 | BL244: Insurance | BM244: 2500
A245: 4 | B245: Emma Brown | C245: Female | D245: 32462 | E245: 555-0104 | F245: emma.brown@example.com | G245: 321 Elm St, Springfield | H245: 46033.791 | I245: 4 | J245: Labour | K245: 45912.302 | L245: 6 | M245: Attending | N245: 45912.312 | O245: 4 | P245: Emma Brown | Q245: Pediatrician | R245: 555-1004 | S245: emma.brown@hospital.com | T245: 4 | U245: 45390.368 | V245: Pediatrics | W245: Cares for infants, children, and adolescents. | X245: 10 | Y245: Tuesday | Z245: 0.33333333 | AA245: 0.58333333 | AB245: 0 | AC245: 4 | AD245: 45670.583 | AE245: complete | AF245: 4 | AG245: 45670.604 | AH245: Routine antenatal check-up. | AI245: 7 | AJ245: High-Risk Pregnancy | AK245: 4 | AL245: 45670.625 | AM245: 7 | AN245: 7 | AO245: Thyroid Function Test | AP245: 900 | AQ245: 4 | AR245: Fasting blood sugar 95 mg/dL | AS245: 45670 | AT245: 25 | AU245: Vitamin D3 | AV245: Cholecalciferol 60000IU | AW245: 60000IU once weekly | AX245: 8 weeks | AY245: 55 | AZ245: 19 | BA245: Uprise D3 | BB245: Cholecalciferol 60000IU | BC245: 50 | BD245: 4 | BE245: 45680 | BF245: 2500 | BG245: 10 | BH245: Doctor Consultation Fee | BI245: 500 | BJ245: 4 | BK245: 45682 | BL245: Insurance | BM245: 2500
A246: 4 | B246: Emma Brown | C246: Female | D246: 32462 | E246: 555-0104 | F246: emma.brown@example.com | G246: 321 Elm St, Springfield | H246: 46033.791 | I246: 4 | J246: Labour | K246: 45912.302 | L246: 6 | M246: Attending | N246: 45912.312 | O246: 4 | P246: Emma Brown | Q246: Pediatrician | R246: 555-1004 | S246: emma.brown@hospital.com | T246: 4 | U246: 45390.368 | V246: Pediatrics | W246: Cares for infants, children, and adolescents. | X246: 11 | Y246: Thursday | Z246: 0.375 | AA246: 0.625 | AB246: 0 | AC246: 4 | AD246: 45670.583 | AE246: complete | AF246: 4 | AG246: 45670.604 | AH246: Routine antenatal check-up. | AI246: 7 | AJ246: High-Risk Pregnancy | AK246: 4 | AL246: 45670.625 | AM246: 7 | AN246: 7 | AO246: Thyroid Function Test | AP246: 900 | AQ246: 4 | AR246: Fasting blood sugar 95 mg/dL | AS246: 45670 | AT246: 25 | AU246: Vitamin D3 | AV246: Cholecalciferol 60000IU | AW246: 60000IU once weekly | AX246: 8 weeks | AY246: 55 | AZ246: 19 | BA246: Uprise D3 | BB246: Cholecalciferol 60000IU | BC246: 50 | BD246: 4 | BE246: 45680 | BF246: 2500 | BG246: 10 | BH246: Doctor Consultation Fee | BI246: 500 | BJ246: 4 | BK246: 45682 | BL246: Insurance | BM246: 2500
A247: 4 | B247: Emma Brown | C247: Female | D247: 32462 | E247: 555-0104 | F247: emma.brown@example.com | G247: 321 Elm St, Springfield | H247: 46033.791 | I247: 4 | J247: Labour | K247: 45912.302 | L247: 6 | M247: Attending | N247: 45912.312 | O247: 4 | P247: Emma Brown | Q247: Pediatrician | R247: 555-1004 | S247: emma.brown@hospital.com | T247: 4 | U247: 45390.368 | V247: Pediatrics | W247: Cares for infants, children, and adolescents. | X247: 12 | Y247: Saturday | Z247: 0.41666667 | AA247: 0.66666667 | AB247: 1 | AC247: 4 | AD247: 45670.583 | AE247: complete | AF247: 4 | AG247: 45670.604 | AH247: Routine antenatal check-up. | AI247: 7 | AJ247: High-Risk Pregnancy | AK247: 4 | AL247: 45670.625 | AM247: 7 | AN247: 7 | AO247: Thyroid Function Test | AP247: 900 | AQ247: 4 | AR247: Fasting blood sugar 95 mg/dL | AS247: 45670 | AT247: 25 | AU247: Vitamin D3 | AV247: Cholecalciferol 60000IU | AW247: 60000IU once weekly | AX247: 8 weeks | AY247: 55 | AZ247: 19 | BA247: Uprise D3 | BB247: Cholecalciferol 60000IU | BC247: 50 | BD247: 4 | BE247: 45680 | BF247: 2500 | BG247: 10 | BH247: Doctor Consultation Fee | BI247: 500 | BJ247: 4 | BK247: 45682 | BL247: Insurance | BM247: 2500
... A271: 4 | B271: Emma Brown | C271: Female | D271: 32462 | E271: 555-0104 | F271: emma.brown@example.com | G271: 321 Elm St, Springfield | H271: 46033.791 | I271: 4 | J271: Labour | K271: 45912.302 | L271: 7 | M271: Consultant | N271: 45912.333 | O271: 18 | P271: Harper Moore | Q271: Oncologist | R271: 555-1018 | S271: harper.moore@hospital.com | T271: 8 | U271: 45512.431 | V271: Oncology | W271: Diagnoses and treats cancer and related conditions. | X271: 54 | Y271: Saturday | Z271: 0.33333333 | AA271: 0.5 | AB271: 0 | AC271: 4 | AD271: 45670.583 | AE271: complete | AF271: 4 | AG271: 45670.604 | AH271: Routine antenatal check-up. | AI271: 7 | AJ271: High-Risk Pregnancy | AK271: 4 | AL271: 45670.625 | AM271: 7 | AN271: 7 | AO271: Thyroid Function Test | AP271: 900 | AQ271: 4 | AR271: Fasting blood sugar 95 mg/dL | AS271: 45670 | AT271: 25 | AU271: Vitamin D3 | AV271: Cholecalciferol 60000IU | AW271: 60000IU once weekly | AX271: 8 weeks | AY271: 55 | AZ271: 19 | BA271: Uprise D3 | BB271: Cholecalciferol 60000IU | BC271: 50 | BD271: 4 | BE271: 45680 | BF271: 2500 | BG271: 12 | BH271: Medicines | BI271: 1700 | BJ271: 4 | BK271: 45682 | BL271: Insurance | BM271: 2500
...

Sheet patients
A1: patient_id | B1: first_name | C1: last_name | D1: gender | E1: date_of_birth | F1: phone | G1: email | H1: address | I1: created_at
A2: 1 | B2: Liam | C2: Smith | D2: Male | E2: 31149 | F2: 555-0101 | G2: liam.smith@example.com | H2: 123 Maple St, Springfield | I2: 46033.791
A3: 2 | B3: Olivia | C3: Johnson | D3: Female | E3: 33107 | F3: 555-0102 | G3: olivia.johnson@example.com | H3: 456 Oak St, Springfield | I3: 46033.791
A4: 3 | B4: Noah | C4: Williams | D4: Male | E4: 28495 | F4: 555-0103 | G4: noah.williams@example.com | H4: 789 Pine St, Springfield | I4: 46033.791
A5: 4 | B5: Emma | C5: Brown | D5: Female | E5: 32462 | F5: 555-0104 | G5: emma.brown@example.com | H5: 321 Elm St, Springfield | I5: 46033.791
A6: 5 | B6: James | C6: Jones | D6: Male | E6: 33754 | F6: 555-0105 | G6: james.jones@example.com | H6: 654 Cedar St, Springfield | I6: 46033.791
A7: 6 | B7: Ava | C7: Garcia | D7: Female | E7: 30515 | F7: 555-0106 | G7: ava.garcia@example.com | H7: 987 Birch St, Springfield | I7: 46033.791
A8: 7 | B8: William | C8: Miller | D8: Male | E8: 34755 | F8: 555-0107 | G8: william.miller@example.com | H8: 147 Spruce St, Springfield | I8: 46033.791
A9: 8 | B9: Sophia | C9: Davis | D9: Female | E9: 29564 | F9: 555-0108 | G9: sophia.davis@example.com | H9: 258 Walnut St, Springfield | I9: 46033.791
A10: 9 | B10: Benjamin | C10: Rodriguez | D10: Male | E10: 27467 | F10: 555-0109 | G10: benjamin.rodriguez@example.com | H10: 369 Chestnut St, Springfield | I10: 46033.791
A11: 10 | B11: Isabella | C11: Martinez | D11: Female | E11: 36059 | F11: 555-0110 | G11: isabella.martinez@example.com | H11: 159 Hickory St, Springfield | I11: 46033.791
A12: 11 | B12: Lucas | C12: Hernandez | D12: Male | E12: 30109 | F12: 555-0111 | G12: lucas.hernandez@example.com | H12: 753 Aspen St, Springfield | I12: 46033.791
A13: 12 | B13: Mia | C13: Lopez | D13: Female | E13: 32061 | F13: 555-0112 | G13: mia.lopez@example.com | H13: 951 Poplar St, Springfield | I13: 46033.791
... A51: 50 | B51: Emily | C51: Turner | D51: Female | E51: 34150 | F51: 555-0150 | G51: emily.turner@example.com | H51: 369 Aspen St, Springfield | I51: 46033.791

Sheet medicines
A1: medicine_id | B1: medicine_name | C1: formula | D1: price
A2: 1 | B2: Paracetamol | C2: Acetaminophen 500mg | D2: 12.5
A3: 2 | B3: Ibuprofen | C3: Ibuprofen 400mg | D3: 18
A4: 3 | B4: Amoxicillin | C4: Amoxicillin 500mg | D4: 45
A5: 4 | B5: Azithromycin | C5: Azithromycin 500mg | D5: 120
A6: 5 | B6: Ciprofloxacin | C6: Ciprofloxacin 500mg | D6: 85
A7: 6 | B7: Metformin | C7: Metformin Hydrochloride 500mg | D7: 30
A8: 7 | B8: Amlodipine | C8: Amlodipine 5mg | D8: 25
A9: 8 | B9: Losartan | C9: Losartan Potassium 50mg | D9: 28
A10: 9 | B10: Atorvastatin | C10: Atorvastatin 10mg | D10: 32
A11: 10 | B11: Aspirin | C11: Acetylsalicylic Acid 75mg | D11: 15
A12: 11 | B12: Pantoprazole | C12: Pantoprazole 40mg | D12: 22
A13: 12 | B13: Omeprazole | C13: Omeprazole 20mg | D13: 20
... A46: 45 | B46: Clopidogrel | C46: Clopidogrel 75mg | D46: 45

Sheet lab_tests
A1: test_id | B1: test_name | C1: cost | D1: prescription_item_id
A2: 1 | B2: ECG | C2: 550 | D2: 1
A3: 2 | B3: Lipid Profile | C3: 1200 | D3: 2
A4: 3 | B4: Chest X-Ray | C4: 800 | D4: 3
A5: 4 | B5: Blood Sugar Test | C5: 300 | D5: 4
A6: 5 | B6: Ultrasound Abdomen | C6: 1500 | D6: 5
A7: 6 | B7: Complete Blood Count | C7: 400 | D7: 6
A8: 7 | B8: Thyroid Function Test | C8: 900 | D8: 7
A9: 8 | B9: Urine Routine Test | C9: 250 | D9: 8
A10: 9 | B10: MRI Brain | C10: 5500 | D10: 9
A11: 10 | B11: HbA1c Test | C11: 700 | D11: 10
A12: 11 | B12: Liver Function Test | C12: 850 | D12: 11
A13: 12 | B13: Kidney Function Test | C13: 850 | D13: 12
... A41: 40 | B41: Biopsy Histopathology | C41: 4500 | D41: 40

Sheet invoice_items
A1: invoice_item_id | B1: bill_id | C1: description | D1: amount
A2: 1 | B2: 1 | C2: Doctor Consultation Fee | D2: 500
A3: 2 | B3: 1 | C3: ECG Test | D3: 500
A4: 3 | B4: 1 | C4: Medicines | D4: 2500
A5: 4 | B5: 2 | C5: Doctor Consultation Fee | D5: 400
A6: 5 | B6: 2 | C6: Lipid Profile Test | D6: 1200
A7: 6 | B7: 2 | C7: Medicines | D7: 2600
A8: 7 | B8: 3 | C8: Doctor Consultation Fee | D8: 400
A9: 8 | B9: 3 | C9: Chest X-Ray | D9: 800
A10: 9 | B10: 3 | C10: Medicines | D10: 600
A11: 10 | B11: 4 | C11: Doctor Consultation Fee | D11: 500
A12: 11 | B12: 4 | C12: Blood Sugar Test | D12: 300
A13: 12 | B13: 4 | C13: Medicines | D13: 1700
... A61: 60 | B61: 20 | C61: Medicines | D61: 0

Sheet doctors
A1: doctor_id | B1: first_name | C1: last_name | D1: specialization | E1: phone | F1: email | G1: department_id | H1: created_at
A2: 1 | B2: Liam | C2: Smith | D2: Cardiologist | E2: 555-1001 | F2: liam.smith@hospital.com | G2: 1 | H2: 45296.396
A3: 2 | B3: Olivia | C3: Johnson | D3: Neurologist | E3: 555-1002 | F3: olivia.johnson@hospital.com | G3: 2 | H3: 45332.427
